import { BackoffStrategy } from './backoff.strategy';
import { RetryCondition } from './retry.condition';
import { Retry } from './retry.decorator';

describe('Retry Decorator', () => {
  interface ArbitraryArg {
    foo: string;
  }
  interface ArbitraryResult {
    bar: string;
  }

  let arbitraryError: Error;
  let arbitraryArg: ArbitraryArg;
  let arbitraryResult: ArbitraryResult;
  let testMock: jest.Mock<Promise<ArbitraryResult>>;

  function assertMethodCalledCorrectly(times: number, arg: ArbitraryArg): void {
    expect(testMock).toHaveBeenCalledTimes(times);
    for (let i = 0; i < times; i++) {
      expect(testMock).toHaveBeenNthCalledWith(i + 1, arg);
    }
  }

  beforeEach(() => {
    testMock = jest.fn();
    arbitraryError = new Error('errr');
    arbitraryArg = {
      foo: 'hello'
    };
    arbitraryResult = {
      bar: 'hi'
    };
  });

  describe('Given a class with a method to retry (no options specified)', () => {
    class TestClass {
      @Retry()
      test(arg1: ArbitraryArg): Promise<ArbitraryResult> {
        return testMock(arg1);
      }
    }

    let testable: TestClass;
    beforeEach(() => {
      testable = new TestClass();
    });

    describe('Given decorated method will not fail', () => {
      beforeEach(() => {
        testMock.mockResolvedValue(arbitraryResult);
      });

      describe('When method is invoked with arbitrary arguments', () => {
        let result: ArbitraryResult;
        beforeEach(async () => {
          result = await testable.test(arbitraryArg);
        });

        test('Then result is successfully returned', () => {
          expect(result).toBe(arbitraryResult);
        });

        test('Then the original method is only called once with the original arguments', () => {
          assertMethodCalledCorrectly(1, arbitraryArg);
        });
      });
    });

    describe('Given decorated method will always fail', () => {
      beforeEach(() => {
        testMock.mockRejectedValue(arbitraryError);
      });

      describe('When method is invoked with arbitrary arguments', () => {
        let thrownError: unknown;
        let startTime: number;
        let totalTime: number;
        beforeEach(async () => {
          try {
            startTime = Date.now();
            await testable.test(arbitraryArg);
            fail('an error should have been thrown but was not');
          } catch (e) {
            totalTime = Date.now() - startTime;
            thrownError = e;
          }
        });

        test('Then last error thrown by original method is thrown', () => {
          expect(thrownError).toBe(arbitraryError);
        });

        test('Then the original method is retried the default number of times', () => {
          assertMethodCalledCorrectly(3, arbitraryArg);
        });

        test('Then there is no noticeable delay', () => {
          expect(totalTime).toBeLessThanOrEqual(50);
        });
      });
    });

    describe('Given decorated method will eventually succeed', () => {
      beforeEach(() => {
        testMock
          .mockRejectedValueOnce(arbitraryError)
          .mockResolvedValue(arbitraryResult);
      });

      describe('When method is invoked with arbitrary arguments', () => {
        let result: ArbitraryResult;
        beforeEach(async () => {
          result = await testable.test(arbitraryArg);
        });

        test('Then result is successfully returned', () => {
          expect(result).toBe(arbitraryResult);
        });

        test('Then the original method is called the correct number of times', () => {
          assertMethodCalledCorrectly(2, arbitraryArg);
        });
      });
    });
  });

  describe('Given a class with a method to retry a specified number of times', () => {
    class TestClass {
      @Retry({ retryAttempts: 3 })
      test(arg1: ArbitraryArg): Promise<ArbitraryResult> {
        return testMock(arg1);
      }
    }

    let testable: TestClass;
    beforeEach(() => {
      testable = new TestClass();
    });

    describe('Given decorated method will always fail', () => {
      beforeEach(() => {
        testMock.mockRejectedValue(arbitraryError);
      });

      describe('When method is invoked with arbitrary arguments', () => {
        let thrownError: unknown;
        beforeEach(async () => {
          try {
            await testable.test(arbitraryArg);
            fail('an error should have been thrown but was not');
          } catch (e) {
            thrownError = e;
          }
        });

        test('Then last error thrown by original method is thrown', () => {
          expect(thrownError).toBe(arbitraryError);
        });

        test('Then the original method is retried the correct number of times', () => {
          assertMethodCalledCorrectly(4, arbitraryArg);
        });
      });
    });
  });

  describe('Given a class with a method to retry with a backoff strategy', () => {
    const smallAmountOfTime = 200;
    class TestBackoffStrategy implements BackoffStrategy {
      getNextBackoffAmount(): number {
        return smallAmountOfTime;
      }
    }
    class TestClass {
      @Retry({ backoffStrategy: new TestBackoffStrategy() })
      test(arg1: ArbitraryArg): Promise<ArbitraryResult> {
        return testMock(arg1);
      }
    }

    let testable: TestClass;
    beforeEach(() => {
      testable = new TestClass();
    });

    describe('Given decorated method will always fail', () => {
      beforeEach(() => {
        testMock.mockRejectedValue(arbitraryError);
      });

      describe('When method is invoked with arbitrary arguments', () => {
        let thrownError: unknown;
        let totalTime: number;
        beforeEach(async () => {
          const startTime = Date.now();
          try {
            await testable.test(arbitraryArg);
            fail('an error should have been thrown but was not');
          } catch (e) {
            thrownError = e;
            totalTime = Date.now() - startTime;
          }
        });

        test('Then last error thrown by original method is thrown', () => {
          expect(thrownError).toBe(arbitraryError);
        });

        test('Then the original method is retried the correct number of times', () => {
          assertMethodCalledCorrectly(3, arbitraryArg);
        });

        test('Then there is a delay between each method call as specified by the backoff policy', () => {
          expect(totalTime).toBeGreaterThanOrEqual(smallAmountOfTime * 2);
        });
      });
    });
  });

  describe('Given a class with a method to retry with a specified retry condition', () => {
    class TestRetryCondition implements RetryCondition<Error> {
      shouldRetry(e: Error): boolean {
        return e === arbitraryError;
      }
    }
    class TestClass {
      @Retry({ retryCondition: new TestRetryCondition() })
      test(arg1: ArbitraryArg): Promise<ArbitraryResult> {
        return testMock(arg1);
      }
    }

    let testable: TestClass;
    beforeEach(() => {
      testable = new TestClass();
    });

    describe('Given decorated method will always fail with error that passes retry condition', () => {
      beforeEach(() => {
        testMock.mockRejectedValue(arbitraryError);
      });

      describe('When method is invoked with arbitrary arguments', () => {
        let thrownError: unknown;
        beforeEach(async () => {
          try {
            await testable.test(arbitraryArg);
            fail('an error should have been thrown but was not');
          } catch (e) {
            thrownError = e;
          }
        });

        test('Then last error thrown by original method is thrown', () => {
          expect(thrownError).toBe(arbitraryError);
        });

        test('Then the original method is retried the correct number of times', () => {
          assertMethodCalledCorrectly(3, arbitraryArg);
        });
      });
    });

    describe('Given decorated method will fail with error that passes retry condition but then fails with error that does not pass retry condition', () => {
      let errorThatDoesNotPassCondition: Error;
      beforeEach(() => {
        errorThatDoesNotPassCondition = new Error('ouch');
        testMock
          .mockRejectedValueOnce(arbitraryError)
          .mockRejectedValue(errorThatDoesNotPassCondition);
      });

      describe('When method is invoked with arbitrary arguments', () => {
        let thrownError: unknown;
        beforeEach(async () => {
          try {
            await testable.test(arbitraryArg);
            fail('an error should have been thrown but was not');
          } catch (e) {
            thrownError = e;
          }
        });

        test('Then last error thrown by original method is thrown', () => {
          expect(thrownError).toBe(errorThatDoesNotPassCondition);
        });

        test('Then the original method is retried the correct number of times', () => {
          assertMethodCalledCorrectly(2, arbitraryArg);
        });
      });
    });
  });
});
